Watching for file changes with StatReloader
Not Found: /api/core/create_room
HTTP POST /api/core/create_room 404 [0.02, 127.0.0.1:43452]
Internal Server Error: /api/core/rooms/
Traceback (most recent call last):
  File "/usr/local/lib/python3.10/dist-packages/django/db/backends/utils.py", line 84, in _execute
    return self.cursor.execute(sql, params)
psycopg2.errors.UndefinedTable: relation "core_room" does not exist
LINE 1: INSERT INTO "core_room" ("name", "created_at", "ended_at") V...
                    ^


The above exception was the direct cause of the following exception:

Traceback (most recent call last):
  File "/usr/local/lib/python3.10/dist-packages/asgiref/sync.py", line 518, in thread_handler
    raise exc_info[1]
  File "/usr/local/lib/python3.10/dist-packages/django/core/handlers/exception.py", line 38, in inner
    response = await get_response(request)
  File "/usr/local/lib/python3.10/dist-packages/django/core/handlers/base.py", line 233, in _get_response_async
    response = await wrapped_callback(request, *callback_args, **callback_kwargs)
  File "/usr/local/lib/python3.10/dist-packages/asgiref/sync.py", line 468, in __call__
    ret = await asyncio.shield(exec_coro)
  File "/usr/lib/python3.10/concurrent/futures/thread.py", line 58, in run
    result = self.fn(*self.args, **self.kwargs)
  File "/usr/local/lib/python3.10/dist-packages/asgiref/sync.py", line 522, in thread_handler
    return func(*args, **kwargs)
  File "/usr/local/lib/python3.10/dist-packages/django/views/decorators/csrf.py", line 54, in wrapped_view
    return view_func(*args, **kwargs)
  File "/home/user/tubonge_apk/tubonge_backend/tubonge_backend/tubonge_server/core/views.py", line 13, in create_room
    room = Room.objects.create(name=name)
  File "/usr/local/lib/python3.10/dist-packages/django/db/models/manager.py", line 85, in manager_method
    return getattr(self.get_queryset(), name)(*args, **kwargs)
  File "/usr/local/lib/python3.10/dist-packages/django/db/models/query.py", line 453, in create
    obj.save(force_insert=True, using=self.db)
  File "/usr/local/lib/python3.10/dist-packages/django/db/models/base.py", line 726, in save
    self.save_base(using=using, force_insert=force_insert,
  File "/usr/local/lib/python3.10/dist-packages/django/db/models/base.py", line 763, in save_base
    updated = self._save_table(
  File "/usr/local/lib/python3.10/dist-packages/django/db/models/base.py", line 868, in _save_table
    results = self._do_insert(cls._base_manager, using, fields, returning_fields, raw)
  File "/usr/local/lib/python3.10/dist-packages/django/db/models/base.py", line 906, in _do_insert
    return manager._insert(
  File "/usr/local/lib/python3.10/dist-packages/django/db/models/manager.py", line 85, in manager_method
    return getattr(self.get_queryset(), name)(*args, **kwargs)
  File "/usr/local/lib/python3.10/dist-packages/django/db/models/query.py", line 1270, in _insert
    return query.get_compiler(using=using).execute_sql(returning_fields)
  File "/usr/local/lib/python3.10/dist-packages/django/db/models/sql/compiler.py", line 1410, in execute_sql
    cursor.execute(sql, params)
  File "/usr/local/lib/python3.10/dist-packages/django/db/backends/utils.py", line 98, in execute
    return super().execute(sql, params)
  File "/usr/local/lib/python3.10/dist-packages/django/db/backends/utils.py", line 66, in execute
    return self._execute_with_wrappers(sql, params, many=False, executor=self._execute)
  File "/usr/local/lib/python3.10/dist-packages/django/db/backends/utils.py", line 75, in _execute_with_wrappers
    return executor(sql, params, many, context)
  File "/usr/local/lib/python3.10/dist-packages/django/db/backends/utils.py", line 79, in _execute
    with self.db.wrap_database_errors:
  File "/usr/local/lib/python3.10/dist-packages/django/db/utils.py", line 90, in __exit__
    raise dj_exc_value.with_traceback(traceback) from exc_value
  File "/usr/local/lib/python3.10/dist-packages/django/db/backends/utils.py", line 84, in _execute
    return self.cursor.execute(sql, params)
django.db.utils.ProgrammingError: relation "core_room" does not exist
LINE 1: INSERT INTO "core_room" ("name", "created_at", "ended_at") V...
                    ^

HTTP POST /api/core/rooms/ 500 [0.11, 127.0.0.1:52694]
HTTP POST /api/core/rooms/ 200 [0.02, 127.0.0.1:34018]
